2018-12-26 01:38:20,689 ERROR: Exception on /get_specialities/ [POST] [in c:\users\admin\appdata\local\programs\python\python37-32\lib\site-packages\flask\app.py:1761]
Traceback (most recent call last):
  File "c:\users\admin\appdata\local\programs\python\python37-32\lib\site-packages\flask\app.py", line 2292, in wsgi_app
    response = self.full_dispatch_request()
  File "c:\users\admin\appdata\local\programs\python\python37-32\lib\site-packages\flask\app.py", line 1815, in full_dispatch_request
    rv = self.handle_user_exception(e)
  File "c:\users\admin\appdata\local\programs\python\python37-32\lib\site-packages\flask\app.py", line 1718, in handle_user_exception
    reraise(exc_type, exc_value, tb)
  File "c:\users\admin\appdata\local\programs\python\python37-32\lib\site-packages\flask\_compat.py", line 35, in reraise
    raise value
  File "c:\users\admin\appdata\local\programs\python\python37-32\lib\site-packages\flask\app.py", line 1813, in full_dispatch_request
    rv = self.dispatch_request()
  File "c:\users\admin\appdata\local\programs\python\python37-32\lib\site-packages\flask\app.py", line 1799, in dispatch_request
    return self.view_functions[rule.endpoint](**req.view_args)
  File "C:\Users\Admin\Desktop\1\py\AbitHelper\app\routes.py", line 31, in get_specialities
    redirect(url_for('get_specialities'), choice = option)
TypeError: redirect() got an unexpected keyword argument 'choice'
2018-12-26 01:38:39,671 INFO: Abithelper startup [in C:\Users\Admin\Desktop\1\py\AbitHelper\app\__init__.py:24]
2018-12-26 01:38:43,413 ERROR: Exception on /get_specialities/ [POST] [in c:\users\admin\appdata\local\programs\python\python37-32\lib\site-packages\flask\app.py:1761]
Traceback (most recent call last):
  File "c:\users\admin\appdata\local\programs\python\python37-32\lib\site-packages\flask\app.py", line 2292, in wsgi_app
    response = self.full_dispatch_request()
  File "c:\users\admin\appdata\local\programs\python\python37-32\lib\site-packages\flask\app.py", line 1816, in full_dispatch_request
    return self.finalize_request(rv)
  File "c:\users\admin\appdata\local\programs\python\python37-32\lib\site-packages\flask\app.py", line 1831, in finalize_request
    response = self.make_response(rv)
  File "c:\users\admin\appdata\local\programs\python\python37-32\lib\site-packages\flask\app.py", line 1957, in make_response
    'The view function did not return a valid response. The'
TypeError: The view function did not return a valid response. The function either returned None or ended without a return statement.
2018-12-26 01:39:16,791 INFO: Abithelper startup [in C:\Users\Admin\Desktop\1\py\AbitHelper\app\__init__.py:24]
2018-12-26 01:41:06,315 INFO: Abithelper startup [in C:\Users\Admin\Desktop\1\py\AbitHelper\app\__init__.py:24]
2018-12-26 01:41:28,068 INFO: Abithelper startup [in C:\Users\Admin\Desktop\1\py\AbitHelper\app\__init__.py:24]
2018-12-26 01:41:30,835 ERROR: Exception on /get_specialities/ [POST] [in c:\users\admin\appdata\local\programs\python\python37-32\lib\site-packages\flask\app.py:1761]
Traceback (most recent call last):
  File "c:\users\admin\appdata\local\programs\python\python37-32\lib\site-packages\flask\app.py", line 2292, in wsgi_app
    response = self.full_dispatch_request()
  File "c:\users\admin\appdata\local\programs\python\python37-32\lib\site-packages\flask\app.py", line 1816, in full_dispatch_request
    return self.finalize_request(rv)
  File "c:\users\admin\appdata\local\programs\python\python37-32\lib\site-packages\flask\app.py", line 1831, in finalize_request
    response = self.make_response(rv)
  File "c:\users\admin\appdata\local\programs\python\python37-32\lib\site-packages\flask\app.py", line 1957, in make_response
    'The view function did not return a valid response. The'
TypeError: The view function did not return a valid response. The function either returned None or ended without a return statement.
2018-12-26 01:44:53,166 INFO: Abithelper startup [in C:\Users\Admin\Desktop\1\py\AbitHelper\app\__init__.py:24]
2018-12-26 01:44:57,429 ERROR: Exception on /get_specialities/ [POST] [in c:\users\admin\appdata\local\programs\python\python37-32\lib\site-packages\flask\app.py:1761]
Traceback (most recent call last):
  File "c:\users\admin\appdata\local\programs\python\python37-32\lib\site-packages\flask\app.py", line 2292, in wsgi_app
    response = self.full_dispatch_request()
  File "c:\users\admin\appdata\local\programs\python\python37-32\lib\site-packages\flask\app.py", line 1815, in full_dispatch_request
    rv = self.handle_user_exception(e)
  File "c:\users\admin\appdata\local\programs\python\python37-32\lib\site-packages\flask\app.py", line 1718, in handle_user_exception
    reraise(exc_type, exc_value, tb)
  File "c:\users\admin\appdata\local\programs\python\python37-32\lib\site-packages\flask\_compat.py", line 35, in reraise
    raise value
  File "c:\users\admin\appdata\local\programs\python\python37-32\lib\site-packages\flask\app.py", line 1813, in full_dispatch_request
    rv = self.dispatch_request()
  File "c:\users\admin\appdata\local\programs\python\python37-32\lib\site-packages\flask\app.py", line 1799, in dispatch_request
    return self.view_functions[rule.endpoint](**req.view_args)
  File "C:\Users\Admin\Desktop\1\py\AbitHelper\app\routes.py", line 27, in get_specialities
    alert(option)
NameError: name 'alert' is not defined
2018-12-26 01:45:40,558 INFO: Abithelper startup [in C:\Users\Admin\Desktop\1\py\AbitHelper\app\__init__.py:24]
2018-12-26 01:46:26,533 INFO: Abithelper startup [in C:\Users\Admin\Desktop\1\py\AbitHelper\app\__init__.py:24]
